{"timestamp": "2025-10-05T13:23:28.256049", "level": "ERROR", "logger": "flask_blog.requests", "message": "Request failed with exception", "module": "logging", "function": "_log_request_error", "line": 260, "event": "request_error", "request_id": "fa4f9a31-6570-4063-b41f-90b8928be6dd", "method": "GET", "url": "http://localhost:5000/users", "path": "/users", "exception_type": "BuildError", "exception_message": "Could not build url for endpoint 'user_profile' with values ['username']. Did you mean 'main.user_profile' instead?", "duration_ms": 0, "remote_addr": "127.0.0.1", "exception": "Traceback (most recent call last):\n  File \"C:\\Users\\Khoa\\AppData\\Local\\Programs\\Python\\Python312\\Lib\\site-packages\\flask\\app.py\", line 2193, in wsgi_app\n    response = self.handle_exception(e)\n               ^^^^^^^^^^^^^^^^^^^^^^^^\n  File \"C:\\Users\\Khoa\\AppData\\Local\\Programs\\Python\\Python312\\Lib\\site-packages\\flask_restx\\api.py\", line 672, in error_router\n    return original_handler(e)\n           ^^^^^^^^^^^^^^^^^^^\n  File \"C:\\Users\\Khoa\\AppData\\Local\\Programs\\Python\\Python312\\Lib\\site-packages\\flask_restful\\__init__.py\", line 298, in error_router\n    return original_handler(e)\n           ^^^^^^^^^^^^^^^^^^^\n  File \"C:\\Users\\Khoa\\AppData\\Local\\Programs\\Python\\Python312\\Lib\\site-packages\\flask\\app.py\", line 2190, in wsgi_app\n    response = self.full_dispatch_request()\n               ^^^^^^^^^^^^^^^^^^^^^^^^^^^^\n  File \"C:\\Users\\Khoa\\AppData\\Local\\Programs\\Python\\Python312\\Lib\\site-packages\\flask\\app.py\", line 1486, in full_dispatch_request\n    rv = self.handle_user_exception(e)\n         ^^^^^^^^^^^^^^^^^^^^^^^^^^^^^\n  File \"C:\\Users\\Khoa\\AppData\\Local\\Programs\\Python\\Python312\\Lib\\site-packages\\flask_restx\\api.py\", line 672, in error_router\n    return original_handler(e)\n           ^^^^^^^^^^^^^^^^^^^\n  File \"C:\\Users\\Khoa\\AppData\\Local\\Programs\\Python\\Python312\\Lib\\site-packages\\flask_restful\\__init__.py\", line 298, in error_router\n    return original_handler(e)\n           ^^^^^^^^^^^^^^^^^^^\n  File \"C:\\Users\\Khoa\\AppData\\Local\\Programs\\Python\\Python312\\Lib\\site-packages\\flask\\app.py\", line 1484, in full_dispatch_request\n    rv = self.dispatch_request()\n         ^^^^^^^^^^^^^^^^^^^^^^^\n  File \"C:\\Users\\Khoa\\AppData\\Local\\Programs\\Python\\Python312\\Lib\\site-packages\\flask\\app.py\", line 1469, in dispatch_request\n    return self.ensure_sync(self.view_functions[rule.endpoint])(**view_args)\n           ^^^^^^^^^^^^^^^^^^^^^^^^^^^^^^^^^^^^^^^^^^^^^^^^^^^^^^^^^^^^^^^^^\n  File \"D:\\Github Copilot\\With flask\\app\\blueprints\\main\\routes.py\", line 54, in users\n    return render_template('users.html', title='Users', users=users)\n           ^^^^^^^^^^^^^^^^^^^^^^^^^^^^^^^^^^^^^^^^^^^^^^^^^^^^^^^^^\n  File \"C:\\Users\\Khoa\\AppData\\Local\\Programs\\Python\\Python312\\Lib\\site-packages\\flask\\templating.py\", line 151, in render_template\n    return _render(app, template, context)\n           ^^^^^^^^^^^^^^^^^^^^^^^^^^^^^^^\n  File \"C:\\Users\\Khoa\\AppData\\Local\\Programs\\Python\\Python312\\Lib\\site-packages\\flask\\templating.py\", line 132, in _render\n    rv = template.render(context)\n         ^^^^^^^^^^^^^^^^^^^^^^^^\n  File \"C:\\Users\\Khoa\\AppData\\Local\\Programs\\Python\\Python312\\Lib\\site-packages\\jinja2\\environment.py\", line 1301, in render\n    self.environment.handle_exception()\n  File \"C:\\Users\\Khoa\\AppData\\Local\\Programs\\Python\\Python312\\Lib\\site-packages\\jinja2\\environment.py\", line 936, in handle_exception\n    raise rewrite_traceback_stack(source=source)\n  File \"D:\\Github Copilot\\With flask\\templates\\users.html\", line 1, in top-level template code\n    {% extends \"base.html\" %}\n  File \"D:\\Github Copilot\\With flask\\templates\\base.html\", line 61, in top-level template code\n    {% block content %}{% endblock %}\n    ^^^^^^^^^^^^^^^^^^^^^^^^^\n  File \"D:\\Github Copilot\\With flask\\templates\\users.html\", line 15, in block 'content'\n    <h3><a href=\"{{ url_for('user_profile', username=user.username) }}\">{{ user.username }}</a></h3>\n    ^^^^^^^^^^^^^^^^^^^^^^^^^\n  File \"C:\\Users\\Khoa\\AppData\\Local\\Programs\\Python\\Python312\\Lib\\site-packages\\flask\\app.py\", line 1697, in url_for\n    return self.handle_url_build_error(error, endpoint, values)\n           ^^^^^^^^^^^^^^^^^^^^^^^^^^^^^^^^^^^^^^^^^^^^^^^^^^^^\n  File \"C:\\Users\\Khoa\\AppData\\Local\\Programs\\Python\\Python312\\Lib\\site-packages\\flask\\app.py\", line 1686, in url_for\n    rv = url_adapter.build(  # type: ignore[union-attr]\n         ^^^^^^^^^^^^^^^^^^^^^^^^^^^^^^^^^^^^^^^^^^^^^^\n  File \"C:\\Users\\Khoa\\AppData\\Local\\Programs\\Python\\Python312\\Lib\\site-packages\\werkzeug\\routing\\map.py\", line 950, in build\n    raise BuildError(endpoint, values, method, self)\nwerkzeug.routing.exceptions.BuildError: Could not build url for endpoint 'user_profile' with values ['username']. Did you mean 'main.user_profile' instead?"}
{"timestamp": "2025-10-06T15:11:21.600750", "level": "ERROR", "logger": "flask_blog.requests", "message": "Request failed with exception", "module": "logging", "function": "_log_request_error", "line": 260, "event": "request_error", "request_id": "1d09f564-14e9-4062-bbe8-c028c9f47a36", "method": "GET", "url": "http://127.0.0.1:5000/", "path": "/", "exception_type": "OperationalError", "exception_message": "(sqlite3.OperationalError) no such column: post.like_count\n[SQL: SELECT post.title AS post_title, post.content AS post_content, post.image_filename AS post_image_filename, post.like_count AS post_like_count, post.view_count AS post_view_count, post.slug AS post_slug, post.meta_description AS post_meta_description, post.user_id AS post_user_id, post.category_id AS post_category_id, post.id AS post_id, post.created_at AS post_created_at, post.updated_at AS post_updated_at \nFROM post ORDER BY post.created_at DESC\n LIMIT ? OFFSET ?]\n[parameters: (5, 0)]\n(Background on this error at: https://sqlalche.me/e/20/e3q8)", "duration_ms": 0, "remote_addr": "127.0.0.1", "exception": "Traceback (most recent call last):\n  File \"C:\\Users\\Khoa\\AppData\\Local\\Programs\\Python\\Python312\\Lib\\site-packages\\sqlalchemy\\engine\\base.py\", line 1969, in _exec_single_context\n    self.dialect.do_execute(\n  File \"C:\\Users\\Khoa\\AppData\\Local\\Programs\\Python\\Python312\\Lib\\site-packages\\sqlalchemy\\engine\\default.py\", line 922, in do_execute\n    cursor.execute(statement, parameters)\nsqlite3.OperationalError: no such column: post.like_count\n\nThe above exception was the direct cause of the following exception:\n\nTraceback (most recent call last):\n  File \"C:\\Users\\Khoa\\AppData\\Local\\Programs\\Python\\Python312\\Lib\\site-packages\\flask\\app.py\", line 2193, in wsgi_app\n    response = self.handle_exception(e)\n               ^^^^^^^^^^^^^^^^^^^^^^^^\n  File \"C:\\Users\\Khoa\\AppData\\Local\\Programs\\Python\\Python312\\Lib\\site-packages\\flask_restx\\api.py\", line 672, in error_router\n    return original_handler(e)\n           ^^^^^^^^^^^^^^^^^^^\n  File \"C:\\Users\\Khoa\\AppData\\Local\\Programs\\Python\\Python312\\Lib\\site-packages\\flask_restful\\__init__.py\", line 298, in error_router\n    return original_handler(e)\n           ^^^^^^^^^^^^^^^^^^^\n  File \"C:\\Users\\Khoa\\AppData\\Local\\Programs\\Python\\Python312\\Lib\\site-packages\\flask\\app.py\", line 2190, in wsgi_app\n    response = self.full_dispatch_request()\n               ^^^^^^^^^^^^^^^^^^^^^^^^^^^^\n  File \"C:\\Users\\Khoa\\AppData\\Local\\Programs\\Python\\Python312\\Lib\\site-packages\\flask\\app.py\", line 1486, in full_dispatch_request\n    rv = self.handle_user_exception(e)\n         ^^^^^^^^^^^^^^^^^^^^^^^^^^^^^\n  File \"C:\\Users\\Khoa\\AppData\\Local\\Programs\\Python\\Python312\\Lib\\site-packages\\flask_restx\\api.py\", line 672, in error_router\n    return original_handler(e)\n           ^^^^^^^^^^^^^^^^^^^\n  File \"C:\\Users\\Khoa\\AppData\\Local\\Programs\\Python\\Python312\\Lib\\site-packages\\flask_restful\\__init__.py\", line 298, in error_router\n    return original_handler(e)\n           ^^^^^^^^^^^^^^^^^^^\n  File \"C:\\Users\\Khoa\\AppData\\Local\\Programs\\Python\\Python312\\Lib\\site-packages\\flask\\app.py\", line 1484, in full_dispatch_request\n    rv = self.dispatch_request()\n         ^^^^^^^^^^^^^^^^^^^^^^^\n  File \"C:\\Users\\Khoa\\AppData\\Local\\Programs\\Python\\Python312\\Lib\\site-packages\\flask\\app.py\", line 1469, in dispatch_request\n    return self.ensure_sync(self.view_functions[rule.endpoint])(**view_args)\n           ^^^^^^^^^^^^^^^^^^^^^^^^^^^^^^^^^^^^^^^^^^^^^^^^^^^^^^^^^^^^^^^^^\n  File \"D:\\Github Copilot\\With flask\\app\\blueprints\\main\\routes.py\", line 19, in home\n    recent_posts = Post.query.order_by(Post.created_at.desc()).limit(5).all()\n                   ^^^^^^^^^^^^^^^^^^^^^^^^^^^^^^^^^^^^^^^^^^^^^^^^^^^^^^^^^^\n  File \"C:\\Users\\Khoa\\AppData\\Local\\Programs\\Python\\Python312\\Lib\\site-packages\\sqlalchemy\\orm\\query.py\", line 2693, in all\n    return self._iter().all()  # type: ignore\n           ^^^^^^^^^^^^\n  File \"C:\\Users\\Khoa\\AppData\\Local\\Programs\\Python\\Python312\\Lib\\site-packages\\sqlalchemy\\orm\\query.py\", line 2847, in _iter\n    result: Union[ScalarResult[_T], Result[_T]] = self.session.execute(\n                                                  ^^^^^^^^^^^^^^^^^^^^^\n  File \"C:\\Users\\Khoa\\AppData\\Local\\Programs\\Python\\Python312\\Lib\\site-packages\\sqlalchemy\\orm\\session.py\", line 2308, in execute\n    return self._execute_internal(\n           ^^^^^^^^^^^^^^^^^^^^^^^\n  File \"C:\\Users\\Khoa\\AppData\\Local\\Programs\\Python\\Python312\\Lib\\site-packages\\sqlalchemy\\orm\\session.py\", line 2190, in _execute_internal\n    result: Result[Any] = compile_state_cls.orm_execute_statement(\n                          ^^^^^^^^^^^^^^^^^^^^^^^^^^^^^^^^^^^^^^^^\n  File \"C:\\Users\\Khoa\\AppData\\Local\\Programs\\Python\\Python312\\Lib\\site-packages\\sqlalchemy\\orm\\context.py\", line 293, in orm_execute_statement\n    result = conn.execute(\n             ^^^^^^^^^^^^^\n  File \"C:\\Users\\Khoa\\AppData\\Local\\Programs\\Python\\Python312\\Lib\\site-packages\\sqlalchemy\\engine\\base.py\", line 1416, in execute\n    return meth(\n           ^^^^^\n  File \"C:\\Users\\Khoa\\AppData\\Local\\Programs\\Python\\Python312\\Lib\\site-packages\\sqlalchemy\\sql\\elements.py\", line 516, in _execute_on_connection\n    return connection._execute_clauseelement(\n           ^^^^^^^^^^^^^^^^^^^^^^^^^^^^^^^^^^\n  File \"C:\\Users\\Khoa\\AppData\\Local\\Programs\\Python\\Python312\\Lib\\site-packages\\sqlalchemy\\engine\\base.py\", line 1639, in _execute_clauseelement\n    ret = self._execute_context(\n          ^^^^^^^^^^^^^^^^^^^^^^\n  File \"C:\\Users\\Khoa\\AppData\\Local\\Programs\\Python\\Python312\\Lib\\site-packages\\sqlalchemy\\engine\\base.py\", line 1848, in _execute_context\n    return self._exec_single_context(\n           ^^^^^^^^^^^^^^^^^^^^^^^^^^\n  File \"C:\\Users\\Khoa\\AppData\\Local\\Programs\\Python\\Python312\\Lib\\site-packages\\sqlalchemy\\engine\\base.py\", line 1988, in _exec_single_context\n    self._handle_dbapi_exception(\n  File \"C:\\Users\\Khoa\\AppData\\Local\\Programs\\Python\\Python312\\Lib\\site-packages\\sqlalchemy\\engine\\base.py\", line 2343, in _handle_dbapi_exception\n    raise sqlalchemy_exception.with_traceback(exc_info[2]) from e\n  File \"C:\\Users\\Khoa\\AppData\\Local\\Programs\\Python\\Python312\\Lib\\site-packages\\sqlalchemy\\engine\\base.py\", line 1969, in _exec_single_context\n    self.dialect.do_execute(\n  File \"C:\\Users\\Khoa\\AppData\\Local\\Programs\\Python\\Python312\\Lib\\site-packages\\sqlalchemy\\engine\\default.py\", line 922, in do_execute\n    cursor.execute(statement, parameters)\nsqlalchemy.exc.OperationalError: (sqlite3.OperationalError) no such column: post.like_count\n[SQL: SELECT post.title AS post_title, post.content AS post_content, post.image_filename AS post_image_filename, post.like_count AS post_like_count, post.view_count AS post_view_count, post.slug AS post_slug, post.meta_description AS post_meta_description, post.user_id AS post_user_id, post.category_id AS post_category_id, post.id AS post_id, post.created_at AS post_created_at, post.updated_at AS post_updated_at \nFROM post ORDER BY post.created_at DESC\n LIMIT ? OFFSET ?]\n[parameters: (5, 0)]\n(Background on this error at: https://sqlalche.me/e/20/e3q8)"}
{"timestamp": "2025-10-08T14:59:09.881915", "level": "ERROR", "logger": "flask_blog.requests", "message": "Request failed with exception", "module": "logging", "function": "_log_request_error", "line": 260, "event": "request_error", "request_id": "a4b032ed-b528-46d5-a6fc-313de7705458", "method": "GET", "url": "http://localhost:5000/blog/", "path": "/blog/", "exception_type": "UndefinedError", "exception_message": "'csrf_token' is undefined", "duration_ms": 0, "remote_addr": "127.0.0.1", "exception": "Traceback (most recent call last):\n  File \"C:\\Users\\Khoa\\AppData\\Local\\Programs\\Python\\Python312\\Lib\\site-packages\\flask\\app.py\", line 2193, in wsgi_app\n    response = self.handle_exception(e)\n               ^^^^^^^^^^^^^^^^^^^^^^^^\n  File \"C:\\Users\\Khoa\\AppData\\Local\\Programs\\Python\\Python312\\Lib\\site-packages\\flask_restx\\api.py\", line 672, in error_router\n    return original_handler(e)\n           ^^^^^^^^^^^^^^^^^^^\n  File \"C:\\Users\\Khoa\\AppData\\Local\\Programs\\Python\\Python312\\Lib\\site-packages\\flask_restful\\__init__.py\", line 298, in error_router\n    return original_handler(e)\n           ^^^^^^^^^^^^^^^^^^^\n  File \"C:\\Users\\Khoa\\AppData\\Local\\Programs\\Python\\Python312\\Lib\\site-packages\\flask\\app.py\", line 2190, in wsgi_app\n    response = self.full_dispatch_request()\n               ^^^^^^^^^^^^^^^^^^^^^^^^^^^^\n  File \"C:\\Users\\Khoa\\AppData\\Local\\Programs\\Python\\Python312\\Lib\\site-packages\\flask\\app.py\", line 1486, in full_dispatch_request\n    rv = self.handle_user_exception(e)\n         ^^^^^^^^^^^^^^^^^^^^^^^^^^^^^\n  File \"C:\\Users\\Khoa\\AppData\\Local\\Programs\\Python\\Python312\\Lib\\site-packages\\flask_restx\\api.py\", line 672, in error_router\n    return original_handler(e)\n           ^^^^^^^^^^^^^^^^^^^\n  File \"C:\\Users\\Khoa\\AppData\\Local\\Programs\\Python\\Python312\\Lib\\site-packages\\flask_restful\\__init__.py\", line 298, in error_router\n    return original_handler(e)\n           ^^^^^^^^^^^^^^^^^^^\n  File \"C:\\Users\\Khoa\\AppData\\Local\\Programs\\Python\\Python312\\Lib\\site-packages\\flask\\app.py\", line 1484, in full_dispatch_request\n    rv = self.dispatch_request()\n         ^^^^^^^^^^^^^^^^^^^^^^^\n  File \"C:\\Users\\Khoa\\AppData\\Local\\Programs\\Python\\Python312\\Lib\\site-packages\\flask\\app.py\", line 1469, in dispatch_request\n    return self.ensure_sync(self.view_functions[rule.endpoint])(**view_args)\n           ^^^^^^^^^^^^^^^^^^^^^^^^^^^^^^^^^^^^^^^^^^^^^^^^^^^^^^^^^^^^^^^^^\n  File \"D:\\Github Copilot\\With flask\\app\\blueprints\\blog\\routes.py\", line 141, in index\n    return render_template('blog/index.html',\n          ^^^^^^^^^^^^^^^^^^^^^^^^^^^^^^^^^^\n  File \"C:\\Users\\Khoa\\AppData\\Local\\Programs\\Python\\Python312\\Lib\\site-packages\\flask\\templating.py\", line 151, in render_template\n    return _render(app, template, context)\n           ^^^^^^^^^^^^^^^^^^^^^^^^^^^^^^^\n  File \"C:\\Users\\Khoa\\AppData\\Local\\Programs\\Python\\Python312\\Lib\\site-packages\\flask\\templating.py\", line 132, in _render\n    rv = template.render(context)\n         ^^^^^^^^^^^^^^^^^^^^^^^^\n  File \"C:\\Users\\Khoa\\AppData\\Local\\Programs\\Python\\Python312\\Lib\\site-packages\\jinja2\\environment.py\", line 1301, in render\n    self.environment.handle_exception()\n  File \"C:\\Users\\Khoa\\AppData\\Local\\Programs\\Python\\Python312\\Lib\\site-packages\\jinja2\\environment.py\", line 936, in handle_exception\n    raise rewrite_traceback_stack(source=source)\n  File \"D:\\Github Copilot\\With flask\\templates\\blog\\index.html\", line 1, in top-level template code\n    {% extends \"base.html\" %}\n  File \"D:\\Github Copilot\\With flask\\templates\\base.html\", line 85, in top-level template code\n    {% block scripts %}{% endblock %}\n    ^^^^^^^^^^^^^^^^^^^^^^^^^\n  File \"D:\\Github Copilot\\With flask\\templates\\blog\\index.html\", line 266, in block 'scripts'\n    'X-CSRFToken': '{{ csrf_token() }}'\n    ^^^^^^^^^^^^^^^^^^^^^^^^^\n  File \"C:\\Users\\Khoa\\AppData\\Local\\Programs\\Python\\Python312\\Lib\\site-packages\\jinja2\\utils.py\", line 83, in from_obj\n    if hasattr(obj, \"jinja_pass_arg\"):\n       ^^^^^^^^^^^^^^^^^^^^^^^^^^^^^^\njinja2.exceptions.UndefinedError: 'csrf_token' is undefined"}
{"timestamp": "2025-10-09T03:56:11.870472", "level": "ERROR", "logger": "flask_blog.requests", "message": "Request failed with exception", "module": "logging", "function": "_log_request_error", "line": 260, "event": "request_error", "request_id": "3776a6de-d391-47e5-b630-19858863ce6e", "method": "GET", "url": "http://localhost:5000/users", "path": "/users", "exception_type": "BuildError", "exception_message": "Could not build url for endpoint 'user_profile' with values ['username']. Did you mean 'main.user_profile' instead?", "duration_ms": 0, "remote_addr": "127.0.0.1", "exception": "Traceback (most recent call last):\n  File \"C:\\Users\\Khoa\\AppData\\Local\\Programs\\Python\\Python312\\Lib\\site-packages\\flask\\app.py\", line 2193, in wsgi_app\n    response = self.handle_exception(e)\n               ^^^^^^^^^^^^^^^^^^^^^^^^\n  File \"C:\\Users\\Khoa\\AppData\\Local\\Programs\\Python\\Python312\\Lib\\site-packages\\flask_restx\\api.py\", line 672, in error_router\n    return original_handler(e)\n           ^^^^^^^^^^^^^^^^^^^\n  File \"C:\\Users\\Khoa\\AppData\\Local\\Programs\\Python\\Python312\\Lib\\site-packages\\flask_restful\\__init__.py\", line 298, in error_router\n    return original_handler(e)\n           ^^^^^^^^^^^^^^^^^^^\n  File \"C:\\Users\\Khoa\\AppData\\Local\\Programs\\Python\\Python312\\Lib\\site-packages\\flask\\app.py\", line 2190, in wsgi_app\n    response = self.full_dispatch_request()\n               ^^^^^^^^^^^^^^^^^^^^^^^^^^^^\n  File \"C:\\Users\\Khoa\\AppData\\Local\\Programs\\Python\\Python312\\Lib\\site-packages\\flask\\app.py\", line 1486, in full_dispatch_request\n    rv = self.handle_user_exception(e)\n         ^^^^^^^^^^^^^^^^^^^^^^^^^^^^^\n  File \"C:\\Users\\Khoa\\AppData\\Local\\Programs\\Python\\Python312\\Lib\\site-packages\\flask_restx\\api.py\", line 672, in error_router\n    return original_handler(e)\n           ^^^^^^^^^^^^^^^^^^^\n  File \"C:\\Users\\Khoa\\AppData\\Local\\Programs\\Python\\Python312\\Lib\\site-packages\\flask_restful\\__init__.py\", line 298, in error_router\n    return original_handler(e)\n           ^^^^^^^^^^^^^^^^^^^\n  File \"C:\\Users\\Khoa\\AppData\\Local\\Programs\\Python\\Python312\\Lib\\site-packages\\flask\\app.py\", line 1484, in full_dispatch_request\n    rv = self.dispatch_request()\n         ^^^^^^^^^^^^^^^^^^^^^^^\n  File \"C:\\Users\\Khoa\\AppData\\Local\\Programs\\Python\\Python312\\Lib\\site-packages\\flask\\app.py\", line 1469, in dispatch_request\n    return self.ensure_sync(self.view_functions[rule.endpoint])(**view_args)\n           ^^^^^^^^^^^^^^^^^^^^^^^^^^^^^^^^^^^^^^^^^^^^^^^^^^^^^^^^^^^^^^^^^\n  File \"D:\\Github Copilot\\With flask\\app\\blueprints\\main\\routes.py\", line 54, in users\n    return render_template('users.html', title='Users', users=users)\n           ^^^^^^^^^^^^^^^^^^^^^^^^^^^^^^^^^^^^^^^^^^^^^^^^^^^^^^^^^\n  File \"C:\\Users\\Khoa\\AppData\\Local\\Programs\\Python\\Python312\\Lib\\site-packages\\flask\\templating.py\", line 151, in render_template\n    return _render(app, template, context)\n           ^^^^^^^^^^^^^^^^^^^^^^^^^^^^^^^\n  File \"C:\\Users\\Khoa\\AppData\\Local\\Programs\\Python\\Python312\\Lib\\site-packages\\flask\\templating.py\", line 132, in _render\n    rv = template.render(context)\n         ^^^^^^^^^^^^^^^^^^^^^^^^\n  File \"C:\\Users\\Khoa\\AppData\\Local\\Programs\\Python\\Python312\\Lib\\site-packages\\jinja2\\environment.py\", line 1301, in render\n    self.environment.handle_exception()\n  File \"C:\\Users\\Khoa\\AppData\\Local\\Programs\\Python\\Python312\\Lib\\site-packages\\jinja2\\environment.py\", line 936, in handle_exception\n    raise rewrite_traceback_stack(source=source)\n  File \"D:\\Github Copilot\\With flask\\templates\\users.html\", line 1, in top-level template code\n    {% extends \"base.html\" %}\n  File \"D:\\Github Copilot\\With flask\\templates\\base.html\", line 73, in top-level template code\n    {% block content %}{% endblock %}\n    ^^^^^^^^^^^^^^^^^^^^^^^^^\n  File \"D:\\Github Copilot\\With flask\\templates\\users.html\", line 15, in block 'content'\n    <h3><a href=\"{{ url_for('user_profile', username=user.username) }}\">{{ user.username }}</a></h3>\n    ^^^^^^^^^^^^^^^^^^^^^^^^^\n  File \"C:\\Users\\Khoa\\AppData\\Local\\Programs\\Python\\Python312\\Lib\\site-packages\\flask\\app.py\", line 1697, in url_for\n    return self.handle_url_build_error(error, endpoint, values)\n           ^^^^^^^^^^^^^^^^^^^^^^^^^^^^^^^^^^^^^^^^^^^^^^^^^^^^\n  File \"C:\\Users\\Khoa\\AppData\\Local\\Programs\\Python\\Python312\\Lib\\site-packages\\flask\\app.py\", line 1686, in url_for\n    rv = url_adapter.build(  # type: ignore[union-attr]\n         ^^^^^^^^^^^^^^^^^^^^^^^^^^^^^^^^^^^^^^^^^^^^^^\n  File \"C:\\Users\\Khoa\\AppData\\Local\\Programs\\Python\\Python312\\Lib\\site-packages\\werkzeug\\routing\\map.py\", line 950, in build\n    raise BuildError(endpoint, values, method, self)\nwerkzeug.routing.exceptions.BuildError: Could not build url for endpoint 'user_profile' with values ['username']. Did you mean 'main.user_profile' instead?"}
